Workbook

Sheet BConstraints Fig 2-1 & 2-2 
A1: Fig 2-1 | AS1: أكتوبر - ديسمبر 2021 | AU1: يناير – مارس 2022 | AW1: أبريل– يونيو 2022 | AZ1: يوليو - سبتمبر 2022 | BB1: أكتوبر - ديسمبر 2022 | BD1: يناير – مارس 2023 | BF1: أبريل– يونيو 2023 | BH1: يوليو - سبتمبر 2023 | BJ1: أكتوبر - ديسمبر 2023 | BK1: يناير – مارس 2024 | BM1: أبريل– يونيو 2024 | BO1: يوليو - سبتمبر 2024 | BQ1: أكتوبر - ديسمبر 2024 | BS1: يناير – مارس 2025 | BU1: أبريل– يونيو 2025 | BW1: يوليو - سبتمبر 2025
E2: Constraints | F2: نوع المعوقات وشدتها | G2: Jan-Mar 2017 | I2: Apr-Jun 2017 | K2: Jul-Sep 2017 | M2: Oct-Dec 2017 | O2: Jan-Mar 2018 | Q2: Apr-Jun 2018 | S2: Jul-Sep 2018 | U2: Oct-Dec 2018 | W2: Jan-Mar 2019 | Y2: Apr-Jun 2019 | AA2: Jul-Sep 2019 | AC2: Oct-Dec 2019 | AE2: Jan-Mar 2020 | AG2: Apr-Jun 2020 | AI2: Jul-Sep 2020 | AK2: Oct-Dec 2020 | AM2: Jan-Mar 2021 | AO2: Apr-Jun 2021 | AQ2: Jul-Sep 2021 | AS2: Oct-Dec 2021 | AU2: Jan-Mar 2022 | AW2: Apr-Jun 2022 | AZ2: Jul-Sep 2022 | BB2: Oct-Dec 2022 | BD2: Jan-Mar 2023 | BF2: Apr-Jun 2023 | BH2: Jul-Sep 2023 | BI2: Oct-Dec 2023 | BK2: Jan-Mar 2024 | BM2: Apr-Jun 2024 | BN2: Apr-Jun 2024 | BO2: Jul-Sep 2024 | BQ2: Oct-Dec 2024 | BS2: Jan-Mar 2025 | BU2: Apr-Jun 2025 | BV2: Apr-Jun 2024 | BW2: Jul-Sep 2025
E3: High costs of energy and water | F3: ارتفاع تكاليف الطاقة والمياه | AM3: 100 | AO3: 100 | AQ3: 100 | AS3: 100 | AU3: 100 | AW3: 100 | AZ3: 74.832962 | BB3: 91.831683 | BD3: 91 | BF3: 86.419753 | BH3: 87.692308 | BJ3: 84.761905 | BL3: _ | BN3: 92.894737 | BP3: 99 | BR3: 79.946524 | BT3: 96.793003 | BV3: 100 | BX3: 89.968652
E4: Export procedures | F4: المشكلات المرتبطة بإجراءات التصدير | AM4: 58.928571 | AO4: 75.387038 | AQ4: 72 | AS4: 89.908257 | AU4: 96.089526 | AW4: 74.914089 | AZ4: 62.583519 | BB4: 80.693069 | BD4: 81 | BF4: 76.54321 | BH4: 76.923077 | BJ4: 67.380952 | BL4: _ | BN4: 14.473684 | BP4: 15 | BR4: 16.042781 | BT4: 14.285714 | BV4: 19.55836 | BX4: 11.285266
E5: Increased government fees | F5: زيادة الرسوم المفروضة على الخدمات الحكومية | AM5: 80.555556 | AO5: 78.108108 | AQ5: 70 | AS5: 58.490315 | AU5: 55.117052 | AW5: 53.930126 | AZ5: 59.910913 | BB5: 56.930693 | BD5: 65 | BF5: 50.123457 | BH5: 53.333333 | BJ5: 55.714286 | BL5: 62.464986 | BN5: 56.052632 | BP5: 61 | BR5: 64.705882 | BT5: 60.349854 | BV5: 64.353312 | BX5: 42.633229
E6: Government procedures | F6: إجراءات التعامل مع الجهات الحكومية | AM6: 40.909091 | AO6: 68.286635 | AQ6: 68 | AS6: 48.620074 | AU6: 42.059548 | AW6: 46.052692 | AZ6: 52.783964 | BB6: 60.643564 | BD6: 61 | BF6: 59.753086 | BH6: 71.025641 | BJ6: 60.47619 | BL6: 69.187675 | BN6: 63.421053 | BP6: 72 | BR6: 72.192513 | BT6: 57.142857 | BV6: 71.608833 | BX6: 49.216301
E7: Taxation system | F7: المنظومة الضريبية | AM7: 36.052632 | AO7: 71.19552 | AQ7: 66 | AS7: 48.25451 | AU7: 45.579175 | AW7: 41.003055 | AZ7: 45.879733 | BB7: 63.861386 | BD7: 67 | BF7: 68.641975 | BH7: 64.102564 | BJ7: 62.380952 | BL7: 71.428571 | BN7: 80.789474 | BP7: 68 | BR7: 60.962567 | BT7: 59.475219 | BV7: 61.829653 | BX7: 57.053292
E8: High inflation | F8: ارتفاع التضخم | AM8: 25.872093 | AO8: 40.150962 | AQ8: 55 | AS8: 58.370516 | AU8: 69.512641 | AW8: 88.065674 | AZ8: 100 | BB8: 100 | BD8: 100 | BF8: 100 | BH8: 99.230769 | BJ8: 100 | BL8: 88.235294 | BN8: 100 | BP8: 100 | BR8: 100 | BT8: 100 | BV8: 96.529968 | BX8: 100
E9: Difficulty in finding qualified labor | F9: صعوبة الحصول علي العمالة المؤهلة | AM9: 29.411765 | AO9: 48.034398 | AQ9: 42 | AS9: 24.492819 | AU9: 21.117764 | AW9: 20.539447 | AZ9: 20.935412 | BB9: 23.267327 | BD9: 25 | BF9: 32.098765 | BH9: 37.435897 | BJ9: 45.952381 | BL9: 38.095238 | BN9: 40.526316 | BP9: 42 | BR9: 33.957219 | BT9: 44.023324 | BV9: 45.425868 | BX9: 59.561129
E10: Customs | F10: المنظومة الجمركية | AM10: 25 | AO10: 45.441045 | AQ10: 39 | AS10: 72.652212 | AU10: 59 | AW10: 54.60882 | AZ10: 19.599109 | BB10: 35.148515 | BD10: 31 | BF10: 30.123457 | BH10: 30.25641 | BJ10: 22.142857 | BL10: 24.64986 | BN10: 28.157895 | BP10: 29 | BR10: 28.074866 | BT10: 27.696793 | BV10: 27.760252 | BX10: 26.332288
E11: Unstable economic policies | F11: تخبط السياسات الاقتصادية | AM11: 21.22093 | AO11: 16.971025 | AQ11: 35 | AS11: 27.326325 | AU11: 35.196274 | AW11: 38.175258 | AZ11: 38.084633 | BB11: 48.514851 | BD11: 51 | BF11: 45.185185 | BH11: 57.435897 | BJ11: 70.47619 | BL11: 73.669468 | BN11: 66.578947 | BP11: 54 | BR11: 50 | BT11: 37.026239 | BV11: 48.264984 | BX11: 33.22884
E12: Power outage | F12: إنقطاع الكهرباء | AM12: 20.294118 | AO12: 28.560993 | AQ12: 23 | AS12: 14.871469 | AU12: 11.273942 | AW12: 8.6853761 | AZ12: 8.6859688 | BB12: 24.009901 | BD12: 18 | BF12: 11.358025 | BH12: 17.692308 | BJ12: 15.714286 | BL12: _ | BN12: 66.315789 | BP12: 7 | BR12: 13.636364 | BT12: 7.2886297 | BV12: 11.987382 | BX12: 9.7178683
E13: Lack of information on domestic and foreign markets | F13: غياب المعلومات عن السوق المحلي والخارجي | AM13: 17.816092 | AO13: 31.458486 | AQ13: 19 | AS13: 10.60137 | AU13: 5.2794411 | AW13: 5.6555937 | AZ13: 4.2316258 | BB13: 22.277228 | BD13: 20 | BF13: 15.308642 | BH13: 17.179487 | BJ13: 14.285714 | BL13: _ | BN13: 43.684211 | BP13: 32 | BR13: 31.283422 | BT13: 18.075802 | BV13: 36.59306 | BX13: 23.197492
E14: Others | F14: أخرى | AM14: - | AO14: - | AQ14: 18 | AS14: 13.738374 | AU14: 8.4471058 | AW14: 5.6555937 | AZ14: 6.2360802 | BB14: 5.9405941 | BD14: 9 | BF14: 8.3950617 | BH14: 5.1282051 | BJ14: 14.285714 | BL14: 11.204482 | BN14: 17.894737 | BP14: 6 | BR14: 17.112299 | BT14: 16.326531 | BV14: 24.921136 | BX14: 13.793103
E15: Government contracts don't give priority to locally manufactured products | F15: عدم تفضيل المنتج المحلي في التعاقدات الحكومية | AM15: - | AO15: 15 | AQ15: 17 | AS15: 20.362872 | AU15: 10.554485 | AW15: 16.814609 | AZ15: 0 | BB15: 2.7227723 | BD15: 2 | BF15: 1.4814815 | BH15: 2.0512821 | BJ15: 5 | BL15: _ | BN15: 28.157895 | BP15: 16 | BR15: 13.101604 | BT15: 8.7463557 | BV15: 8.8328076 | BX15: 7.523511
E16: Unfair competition from the state | F16: المنافسة غير العادلة من الدولة | AM16: 58.333333 | AO16: 29.506571 | AQ16: 11 | AS16: 4.5380306 | AU16: 1.7895147 | AW16: 1.9122887 | AZ16: 0 | BB16: 1.7326733 | BD16: 1 | BF16: 0 | BH16: 0 | BJ16: 4.2857143 | BL16: _ | BN16: 38.421053 | BP16: 33 | BR16: 27.540107 | BT16: 22.44898 | BV16: 21.451104 | BX16: 10.344828
E17: Difficulty in obtaining funding | F17: صعوبة الحصول على التمويل | AM17: 8.7349398 | AO17: 11.802628 | AQ17: 10 | AS17: 9.0174337 | AU17: 4.4789603 | AW17: 4.0257316 | AZ17: 2.6726058 | BB17: 8.1683168 | BD17: 9 | BF17: 6.6666667 | BH17: 10 | BJ17: 15.47619 | BL17: 21.288515 | BN17: 24.473684 | BP17: 21 | BR17: 27.272727 | BT17: 25.655977 | BV17: 26.81388 | BX17: 25.07837
E18: Economic policy uncertainty | F18: عدم وضوح توجهات السياسة الاقتصادية في المستقبل | AM18: 5.7228916 | AO18: 9.1891892 | AQ18: 9 | AS18: 9.0174337 | AU18: 4 | AW18: 4.0257316 | AZ18: 1.7817372 | BB18: 7.4257426 | BD18: 8 | BF18: 6.4197531 | BH18: 8.2051282 | BJ18: 11.666667 | BL18: _ | BN18: 77.368421 | BP18: 79 | BR18: 66.042781 | BT18: 58.017493 | BV18: 70.977918 | BX18: 42.946708
E19: Exchange rate | F19: سعر الصرف | AM19: 12.804878 | AO19: 9.5203311 | AQ19: 5 | AS19: 0.91391117 | AU19: 56.369712 | AW19: 73.325825 | AZ19: 84.187082 | BB19: 89.851485 | BD19: 92 | BF19: 96.049383 | BH19: 100 | BJ19: 97.380952 | BL19: 100 | BN19: 68.421053 | BP19: 51 | BR19: 69.518717 | BT19: 45.772595 | BV19: 41.640379 | BX19: 33.855799
E20: Transportation and logistics | F20: النقل واللوجستيات | AM20: 3.9156627 | AO20: 4.5945946 | AQ20: 3 | AS20: 1.878632 | AU20: 7 | AW20: 4.0257316 | AZ20: 2.0044543 | BB20: 21.782178 | BD20: 25 | BF20: 22.469136 | BH20: 33.333333 | BJ20: 36.190476 | BL20: _ | BN20: 31.052632 | BP20: 30 | BR20: 25.13369 | BT20: 39.941691 | BV20: 40.378549 | BX20: 46.081505
A22: Fig 2-2 | G22: Jan-Mar 2017 | I22: Apr-Jun 2017 | K22: Jul-Sep 2017 | M22: Oct-Dec 2017 | O22: Jan-Mar 2018 | Q22: Apr-Jun 2018 | S22: Jul-Sep 2018 | U22: Oct-Dec 2018 | W22: Jan-Mar 2019 | Y22: Apr-Jun 2019 | AA22: Jul-Sep 2019 | AC22: Oct-Dec 2019 | AE22: Jan-Mar 2020 | AG22: Apr-Jun 2020 | AI22: Jul-Sep 2020 | AK22: Oct-Dec 2020 | AM22: Jan-Mar 2021 | AO22: Apr-Jun 2021 | AQ22: Jul-Sep 2021 | AS22: Oct-Dec 2021 | AU22: Jan-Mar 2022 | AW22: Apr-Jun 2022 | AY22: Jul-Sep 2022 | BA22: Oct-Dec 2022 | BC22: Jan-Mar 2023 | BE22: Apr-Jun 2023 | BG22: Jul-Sep 2023 | BI22: Oct-Dec 2023 | BK22: Jan-Mar 2024 | BM22: Apr-Jun 2024 | BO22: Jul-Sep 2024 | BQ22: Oct-Dec 2024 | BS22: Jan-Mar 2025 | BU22: Apr-Jun 2025 | BW22: Jul-Sep 2025
A23: الشركات الكبيرة | B23: الشركات الصغيرة والمتوسطة | C23: Large | D23: SMEs | E23: Constraints | F23: نوع المعوقات وشدتها | G23: الشركات الكبيرة | H23: الشركات الصغيرة والمتوسطة | I23: الشركات الكبيرة | J23: الشركات الصغيرة والمتوسطة | K23: الشركات الكبيرة | L23: الشركات الصغيرة والمتوسطة | M23: الشركات الكبيرة | N23: الشركات الصغيرة والمتوسطة | O23: الشركات الكبيرة | P23: الشركات الصغيرة والمتوسطة | Q23: الشركات الكبيرة | R23: الشركات الصغيرة والمتوسطة | S23: الشركات الكبيرة | T23: الشركات الصغيرة والمتوسطة | U23: الشركات الكبيرة | V23: الشركات الصغيرة والمتوسطة | W23: الشركات الكبيرة | X23: الشركات الصغيرة والمتوسطة | Y23: الشركات الكبيرة | Z23: الشركات الصغيرة والمتوسطة | AA23: الشركات الكبيرة | AB23: الشركات الصغيرة والمتوسطة | AC23: الشركات الكبيرة | AD23: الشركات الصغيرة والمتوسطة | AE23: الشركات الكبيرة | AF23: الشركات الصغيرة والمتوسطة | AG23: الشركات الكبيرة | AH23: الشركات الصغيرة والمتوسطة | AI23: الشركات الكبيرة | AJ23: الشركات الصغيرة والمتوسطة | AK23: الشركات الكبيرة | AL23: الشركات الصغيرة والمتوسطة | AM23: الشركات الكبيرة | AN23: الشركات الصغيرة والمتوسطة | AO23: الشركات الكبيرة | AP23: الشركات الصغيرة والمتوسطة | AQ23: الشركات الكبيرة | AR23: الشركات الصغيرة والمتوسطة | AS23: الشركات الكبيرة | AT23: الشركات الصغيرة والمتوسطة | AU23: الشركات الكبيرة | AV23: الشركات الصغيرة والمتوسطة | AW23: الشركات الكبيرة | AX23: الشركات الصغيرة والمتوسطة | AY23: الشركات الكبيرة | AZ23: الشركات الصغيرة والمتوسطة | BA23: الشركات الكبيرة | BB23: الشركات الصغيرة والمتوسطة | BC23: الشركات الكبيرة | BD23: الشركات الصغيرة والمتوسطة | BE23: الشركات الكبيرة | BF23: الشركات الصغيرة والمتوسطة | BG23: الشركات الكبيرة | BH23: الشركات الصغيرة والمتوسطة | BI23: الشركات الكبيرة | BJ23: الشركات الصغيرة والمتوسطة | BK23: الشركات الكبيرة | BL23: الشركات الصغيرة والمتوسطة | BM23: الشركات الكبيرة | BN23: الشركات الصغيرة والمتوسطة | BO23: الشركات الكبيرة | BP23: الشركات الصغيرة والمتوسطة | BQ23: الشركات الكبيرة | BR23: الشركات الصغيرة والمتوسطة | BS23: الشركات الكبيرة | BT23: الشركات الصغيرة والمتوسطة | BU23: الشركات الكبيرة | BV23: الشركات الصغيرة والمتوسطة | BW23: الشركات الكبيرة | BX23: الشركات الصغيرة والمتوسطة
E24: High costs of energy and water | F24: ارتفاع تكاليف الطاقة والمياه | AO24: 100 | AP24: 76.109937 | AQ24: 98 | AR24: 73 | AS24: 100 | AT24: 100 | AU24: 99.275 | AV24: 100 | AW24: 90.461717 | AX24: 100 | AY24: 81.707317 | AZ24: 73.297003 | BA24: 88.75 | BB24: 92.592593 | BC24: 96 | BD24: 90 | BE24: 89.041096 | BF24: 85.843373 | BG24: 98.684211 | BH24: 83.17757 | BI24: 85.526316 | BJ24: 84.104046 | BK24: 100 | BL24: 75.838926 | BM24: 80 | BN24: 95.555556 | BO24: 94 | BP24: 100 | BQ24: 68.656716 | BR24: 82.410423 | BS24: 71.875 | BT24: 100 | BU24: 95 | BV24: 100 | BW24: 96.666667 | BX24: 88.416988
E25: Export procedures | F25: المشكلات المرتبطة بإجراءات التصدير | AO25: 71.157495 | AP25: 69.93007 | AQ25: 58 | AR25: 63 | AS25: 91.525424 | AT25: 89.552239 | AU25: 100 | AV25: 94.776119 | AW25: 60.307811 | AX25: 77.056277 | AY25: 59.756098 | AZ25: 63.215259 | BA25: 82.5 | BB25: 80.246914 | BC25: 79 | BD25: 81 | BE25: 84.931507 | BF25: 74.698795 | BG25: 85.526316 | BH25: 73.208723 | BI25: 65.789474 | BJ25: 67.34104 | BK25: 76.666667 | BL25: 69.463087 | BM25: 24.615385 | BN25: 12.380952 | BO25: 28 | BP25: 13 | BQ25: 20.895522 | BR25: 14.983713 | BS25: 7.8125 | BT25: 15.384615 | BU25: 30 | BV25: 16.923077 | BW25: 16.666667 | BX25: 10.03861
E26: Increased government fees | F26: زيادة الرسوم المفروضة على الخدمات الحكومية | AO26: 56.451613 | AP26: 82.01581 | AQ26: 72 | AR26: 68 | AS26: 52.146508 | AT26: 59.917199 | AU26: 70.857438 | AV26: 51.601277 | AW26: 55.319149 | AX26: 51.987145 | AY26: 62.195122 | AZ26: 59.400545 | BA26: 43.75 | BB26: 60.185185 | BC26: 51 | BD26: 68 | BE26: 53.424658 | BF26: 49.39759 | BG26: 44.736842 | BH26: 54.205607 | BI26: 46.052632 | BJ26: 57.514451 | BK26: 55 | BL26: 63.758389 | BM26: 41.538462 | BN26: 59.047619 | BO26: 58 | BP26: 61 | BQ26: 58.208955 | BR26: 66.123779 | BS26: 37.5 | BT26: 63.986014 | BU26: 45 | BV26: 68.076923 | BW26: 40 | BX26: 43.243243
E27: Government procedures | F27: إجراءات التعامل مع الجهات الحكومية | AO27: 59.139785 | AP27: 100 | AQ27: 100 | AR27: 100 | AS27: 53.130405 | AT27: 47.574705 | AU27: 54.593573 | AV27: 39.266311 | AW27: 51.06383 | AX27: 43.524121 | AY27: 52.439024 | AZ27: 52.861035 | BA27: 55 | BB27: 62.037037 | BC27: 56 | BD27: 62 | BE27: 60.273973 | BF27: 59.638554 | BG27: 61.842105 | BH27: 71.65109 | BI27: 51.315789 | BJ27: 62.138728 | BK27: 73.333333 | BL27: 68.120805 | BM27: 47.692308 | BN27: 66.666667 | BO27: 64 | BP27: 73 | BQ27: 77.61194 | BR27: 71.009772 | BS27: 32.8125 | BT27: 61.188811 | BU27: 75 | BV27: 70 | BW27: 38.333333 | BX27: 51.737452
E28: Taxation system | F28: المنظومة الضريبية | AO28: 48.387097 | AP28: 75.268817 | AQ28: 72 | AR28: 64 | AS28: 42.307544 | AT28: 49.594385 | AU28: 35.258349 | AV28: 46.872873 | AW28: 46.808511 | AX28: 38.446307 | AY28: 29.268293 | AZ28: 49.591281 | BA28: 50 | BB28: 67.283951 | BC28: 42 | BD28: 73 | BE28: 53.424658 | BF28: 71.987952 | BG28: 50 | BH28: 66.043614 | BI28: 47.368421 | BJ28: 65.317919 | BK28: 60 | BL28: 73.489933 | BM28: 70.769231 | BN28: 82.857143 | BO28: 64 | BP28: 69 | BQ28: 49.253731 | BR28: 63.517915 | BS28: 45.3125 | BT28: 61.188811 | BU28: 50 | BV28: 63.846154 | BW28: 40 | BX28: 61.003861
E29: High inflation | F29: ارتفاع التضخم | AO29: 53.763441 | AP29: 48.875855 | AQ29: 44 | AR29: 42 | AS29: 65.921058 | AT29: 56.577776 | AU29: 87.57719 | AV29: 65.375323 | AW29: 100 | AX29: 82.69583 | AY29: 100 | AZ29: 100 | BA29: 100 | BB29: 100 | BC29: 100 | BD29: 100 | BE29: 100 | BF29: 100 | BG29: 100 | BH29: 96.884735 | BI29: 97.368421 | BJ29: 100 | BK29: 95 | BL29: 86.577181 | BM29: 100 | BN29: 100 | BO29: 100 | BP29: 99 | BQ29: 100 | BR29: 100 | BS29: 100 | BT29: 97.552448 | BU29: 100 | BV29: 94.615385 | BW29: 100 | BX29: 100
E30: Difficulty in finding qualified labor | F30: صعوبة الحصول علي العمالة المؤهلة | AO30: 42.694497 | AP30: 42.383292 | AQ30: 42 | AR30: 39 | AS30: 18.694031 | AT30: 25.807033 | AU30: 15.923125 | AV30: 21.791774 | AW30: 23.404255 | AX30: 19.263873 | AY30: 25.609756 | AZ30: 19.891008 | BA30: 12.5 | BB30: 25.925926 | BC30: 27 | BD30: 25 | BE30: 28.767123 | BF30: 32.831325 | BG30: 40.789474 | BH30: 35.825545 | BI30: 51.315789 | BJ30: 44.508671 | BK30: 58.333333 | BL30: 33.892617 | BM30: 35.384615 | BN30: 41.587302 | BO30: 50 | BP30: 41 | BQ30: 44.776119 | BR30: 31.596091 | BS30: 21.875 | BT30: 47.902098 | BU30: 33.333333 | BV30: 47.692308 | BW30: 55 | BX30: 61.003861
E31: Customs | F31: المنظومة الجمركية | AO31: 59.772296 | AP31: 17.106549 | AQ31: 33 | AR31: 31 | AS31: 63.057885 | AT31: 72.415522 | AU31: 40.853909 | AV31: 67 | AW31: 41.555851 | AX31: 58.418381 | AY31: 31.707317 | AZ31: 16.893733 | BA31: 47.5 | BB31: 32.098765 | BC31: 46 | BD31: 27 | BE31: 47.945205 | BF31: 26.204819 | BG31: 47.368421 | BH31: 25.545171 | BI31: 31.578947 | BJ31: 19.942197 | BK31: 40 | BL31: 21.47651 | BM31: 43.076923 | BN31: 25.079365 | BO31: 52 | BP31: 25 | BQ31: 50.746269 | BR31: 23.127036 | BS31: 28.125 | BT31: 26.923077 | BU31: 40 | BV31: 24.615385 | BW31: 31.666667 | BX31: 25.096525
E32: Unstable economic policies | F32: تخبط السياسات الاقتصادية | AO32: 16.129032 | AP32: 37.634409 | AQ32: 58 | AR32: 55 | AS32: 32.542373 | AT32: 26.255851 | AU32: 48.906742 | AV32: 32.276496 | AW32: 34.042553 | AX32: 37.962706 | AY32: 34.146341 | AZ32: 38.964578 | BA32: 47.5 | BB32: 48.765432 | BC32: 41 | BD32: 53 | BE32: 46.575342 | BF32: 44.879518 | BG32: 52.631579 | BH32: 57.320872 | BI32: 68.421053 | BJ32: 70.520231 | BK32: 81.666667 | BL32: 71.812081 | BM32: 69.230769 | BN32: 66.031746 | BO32: 56 | BP32: 53 | BQ32: 37.313433 | BR32: 52.76873 | BS32: 14.0625 | BT32: 41.258741 | BU32: 38.333333 | BV32: 50 | BW32: 35 | BX32: 32.818533
E33: Power outage | F33: إنقطاع الكهرباء | AO33: 37.634409 | AP33: - | AQ33: 14 | AR33: 15 | AS33: 9.8389638 | AT33: 16.034188 | AU33: 6.2155647 | AV33: 11.923801 | AW33: 9.5744681 | AX33: 8.2212229 | AY33: 1.2195122 | AZ33: 10.354223 | BA33: 18.75 | BB33: 25.308642 | BC33: 12 | BD33: 20 | BE33: 9.5890411 | BF33: 11.746988 | BG33: 15.789474 | BH33: 17.757009 | BI33: 10.526316 | BJ33: 16.763006 | BK33: 6.6666667 | BL33: 28.52349 | BM33: 46.153846 | BN33: 70.47619 | BO33: 3 | BP33: 8 | BQ33: 8.9552239 | BR33: 14.65798 | BS33: 6.25 | BT33: 7.3426573 | BU33: 15 | BV33: 11.153846 | BW33: 11.666667 | BX33: 9.2664093
E34: Lack of information on domestic and foreign markets | F34: غياب المعلومات عن السوق المحلي والخارجي | AO34: 26.88172 | AP34: 12.487512 | AQ34: 12 | AR34: 11 | AS34: 9.8389638 | AT34: 10.771631 | AU34: 13.648393 | AV34: 3.70049 | AW34: 10.638298 | AX34: 4.3524121 | AY34: 4.8780488 | AZ34: 4.0871935 | BA34: 15 | BB34: 24.074074 | BC34: 20 | BD34: 20 | BE34: 19.178082 | BF34: 14.457831 | BG34: 5.2631579 | BH34: 19.626168 | BI34: 6.5789474 | BJ34: 15.895954 | BK34: 13.333333 | BL34: 18.456376 | BM34: 40 | BN34: 44.444444 | BO34: 31 | BP34: 32 | BQ34: 31.343284 | BR34: 31.270358 | BS34: 9.375 | BT34: 19.58042 | BU34: 23.333333 | BV34: 39.230769 | BW34: 25 | BX34: 22.779923
E35: Others | F35: أخرى | AO35: - | AP35: 26.88172 | AQ35: 32 | AR35: 24 | AS35: 3.2808946 | AT35: 16.492377 | AU35: 4.5494644 | AV35: 9.0456422 | AW35: 12.765957 | AX35: 3.8688108 | AY35: 0 | AZ35: 7.6294278 | BA35: 5 | BB35: 6.1728395 | BC35: 0 | BD35: 12 | BE35: 4.109589 | BF35: 9.3373494 | BG35: 0 | BH35: 6.2305296 | BI35: 15.789474 | BJ35: 13.872832 | BK35: 8.3333333 | BL35: 11.744966 | BM35: 18.461538 | BN35: 17.777778 | BO35: 6 | BP35: 6 | BQ35: 17.910448 | BR35: 16.938111 | BS35: 12.5 | BT35: 16.783217 | BU35: 20 | BV35: 25.769231 | BW35: 6.6666667 | BX35: 15.444015
E36: Government contracts don't give priority to locally manufactured products | F36: عدم تفضيل المنتج المحلي في التعاقدات الحكومية | AO36: 17.281106 | AP36: 14.167651 | AQ36: 26 | AR36: 15 | AS36: 6.779661 | AT36: 23.137318 | AU36: 0 | AV36: 12.089552 | AW36: 10.055102 | AX36: 18.705009 | AY36: 0 | AZ36: 0 | BA36: 1.25 | BB36: 3.0864198 | BC36: 2 | BD36: 2 | BE36: 0 | BF36: 1.8072289 | BG36: 5.2631579 | BH36: 1.2461059 | BI36: 3.9473684 | BJ36: 5.2023121 | BK36: 15 | BL36: 9.7315436 | BM36: 23.076923 | BN36: 29.206349 | BO36: 14 | BP36: 16 | BQ36: 8.9552239 | BR36: 14.006515 | BS36: 3.125 | BT36: 9.7902098 | BU36: 10 | BV36: 8.4615385 | BW36: 3.3333333 | BX36: 8.4942085
E37: Unfair competition from the state | F37: المنافسة غير العادلة من الدولة | AO37: 43.010753 | AP37: 32.258065 | AQ37: 28 | AR37: 20 | AS37: 6.5084746 | AT37: 4.1230768 | AU37: 3.4120983 | AV37: 1.4692164 | AW37: 3.3244681 | AX37: 1.2974144 | AY37: 0 | AZ37: 0 | BA37: 0 | BB37: 2.1604938 | BC37: 2 | BD37: 1 | BE37: 0 | BF37: 0 | BG37: 0 | BH37: 0 | BI37: 3.9473684 | BJ37: 4.3352601 | BK37: 18.333333 | BL37: 7.0469799 | BM37: 27.692308 | BN37: 40.634921 | BO37: 36 | BP37: 32 | BQ37: 29.850746 | BR37: 27.035831 | BS37: 7.8125 | BT37: 25.174825 | BU37: 16.666667 | BV37: 22.307692 | BW37: 5 | BX37: 11.583012
E38: Difficulty in obtaining funding | F38: صعوبة الحصول على التمويل | AO38: 8.0645161 | AP38: 7.8201369 | AQ38: 4 | AR38: 5 | AS38: 1.6949153 | AT38: 11.042582 | AU38: 0 | AV38: 5 | AW38: 4.5230858 | AX38: 3.729433 | AY38: 0 | AZ38: 3.2697548 | BA38: 2.5 | BB38: 9.5679012 | BC38: 5 | BD38: 11 | BE38: 5.4794521 | BF38: 6.9277108 | BG38: 10.526316 | BH38: 9.6573209 | BI38: 21.052632 | BJ38: 14.16185 | BK38: 25 | BL38: 20.469799 | BM38: 29.230769 | BN38: 23.492063 | BO38: 19 | BP38: 22 | BQ38: 44.776119 | BR38: 23.452769 | BS38: 20.3125 | BT38: 26.223776 | BU38: 36.666667 | BV38: 24.230769 | BW38: 18.333333 | BX38: 26.640927
E39: Economic policy uncertainty | F39: عدم وضوح توجهات السياسة الاقتصادية في المستقبل | AO39: 8.5388994 | AP39: 19.061584 | AQ39: 4 | AR39: 7 | AS39: 3.3898305 | AT39: 10.562469 | AU39: 0 | AV39: 5 | AW39: 3.0153906 | AX39: 4.2622091 | AY39: 0 | AZ39: 2.1798365 | BA39: 2.5 | BB39: 8.6419753 | BC39: 4 | BD39: 8 | BE39: 5.4794521 | BF39: 6.626506 | BG39: 9.2105263 | BH39: 7.788162 | BI39: 9.2105263 | BJ39: 12.138728 | BK39: 30 | BL39: 18.456376 | BM39: 81.538462 | BN39: 76.507937 | BO39: 80 | BP39: 78 | BQ39: 59.701493 | BR39: 67.42671 | BS39: 43.75 | BT39: 59.79021 | BU39: 56.666667 | BV39: 73.461538 | BW39: 38.333333 | BX39: 44.015444
E40: Exchange rate | F40: سعر الصرف | AO40: 13.44086 | AP40: 26.973027 | AQ40: 12 | AR40: 9 | AS40: 1.9677928 | AT40: 4.4881797 | AU40: 0 | AV40: 1.850245 | AW40: 2.1276596 | AX40: 1.450804 | AY40: 2.4390244 | AZ40: 1.3623978 | BA40: 7.5 | BB40: 13.888889 | BC40: 10 | BD40: 13 | BE40: 12.328767 | BF40: 5.4216867 | BG40: 5.2631579 | BH40: 5.9190031 | BI40: 5.2631579 | BJ40: 4.0462428 | BK40: 0 | BL40: 8.0536913 | BM40: 84.615385 | BN40: 65.079365 | BO40: 56 | BP40: 49 | BQ40: 64.179104 | BR40: 70.684039 | BS40: 53.125 | BT40: 43.006993 | BU40: 53.333333 | BV40: 38.461538 | BW40: 26.666667 | BX40: 35.521236
E41: Transportation and logistics | F41: النقل واللوجستيات | AO41: 18.817204 | AP41: 9.2864125 | AQ41: 7 | AR41: 9 | AS41: 1.9677928 | AT41: 0.67322695 | AU41: 78.478261 | AV41: 51.632463 | AW41: 75.031398 | AX41: 70.605797 | AY41: 84.146341 | AZ41: 84.196185 | BA41: 91.25 | BB41: 89.506173 | BC41: 95 | BD41: 92 | BE41: 98.630137 | BF41: 95.481928 | BG41: 90.789474 | BH41: 100 | BI41: 100 | BJ41: 96.242775 | BK41: 98.333333 | BL41: 100 | BM41: 29.230769 | BN41: 31.428571 | BO41: 41 | BP41: 27 | BQ41: 28.358209 | BR41: 24.429967 | BS41: 42.1875 | BT41: 38.461538 | BU41: 46.666667 | BV41: 38.461538 | BW41: 36.666667 | BX41: 48.262548
...

Sheet Sectoral Constraints Fig 2-3 AR
B1: يناير - مارس 2017 | H1: أبريل - يونيو 2017 | N1: يوليو - سبتمبر 2017 | T1: أكتوبر-ديسمبر 2017 | Z1: يناير - مارس 2018 | AF1: أبريل - يونيو 2018 | AL1: يوليو - سبتمبر 2018 | AR1: أكتوبر-ديسمبر 2018 | AX1: يناير - مارس 2019 | BD1: أبريل - يونيو 2019 | BJ1: يوليو - سبتمبر 2019 | BP1: أكتوبر-ديسمبر 2019 | BV1: يناير - مارس 2020 | CB1: أبريل - يونيو 2020 | CH1: يوليو - سبتمبر 2020 | CN1: أكتوبر-ديسمبر 2020 | CT1: يناير - مارس 2021 | CZ1: أبريل - يونيو 2021 | DF1: يوليو - سبتمبر 2021 | DL1: أكتوبر-ديسمبر 2021 | DR1: يناير- مارس 2022 | DX1: أبريل- يونيو 2022 | ED1: يوليو - سبتمبر 2022 | EJ1: أكتوبر - ديسمبر 2022 | EP1: يناير - مارس 2023 | EV1: أبريل- يونيو 2023 | FB1: يوليو-سبتمبر 2023 | FH1: أكتوبر - ديسمبر 2023 | FN1: يناير - مارس 2024 | FT1: أبريل - يونيو 2024 | FZ1: يوليو-سبتمبر 2024 | GF1: أكتوبر - ديسمبر 2024 | GL1: يناير - مارس 2024 | GR1: أبريل - يونيو 2025 | GX1: يوليو-سبتمبر 2024
B5: قطاع الصناعة التحويلية | C5: قطاع التشييد والبناء | D5: قطاع السياحة | E5: قطاع النقل | F5: قطاع الاتصالات | G5: قطاع الخدمات المالية | H5: قطاع الصناعة التحويلية | I5: قطاع التشييد والبناء | J5: قطاع السياحة | K5: قطاع النقل | L5: قطاع الاتصالات | M5: قطاع الخدمات المالية | N5: قطاع الصناعة التحويلية | O5: قطاع التشييد والبناء | P5: قطاع السياحة | Q5: قطاع النقل | R5: قطاع الاتصالات | S5: قطاع الخدمات المالية | T5: قطاع الصناعة التحويلية | U5: قطاع التشييد والبناء | V5: قطاع السياحة | W5: قطاع النقل | X5: قطاع الاتصالات | Y5: قطاع الخدمات المالية | Z5: قطاع الصناعة التحويلية | AA5: قطاع التشييد والبناء | AB5: قطاع السياحة | AC5: قطاع النقل | AD5: قطاع الاتصالات | AE5: قطاع الخدمات المالية | AF5: قطاع الصناعة التحويلية | AG5: قطاع التشييد والبناء | AH5: قطاع السياحة | AI5: قطاع النقل | AJ5: قطاع الاتصالات | AK5: قطاع الخدمات المالية | AL5: قطاع الصناعة التحويلية | AM5: قطاع التشييد والبناء | AN5: قطاع السياحة | AO5: قطاع النقل | AP5: قطاع الاتصالات | AQ5: قطاع الخدمات المالية | AR5: قطاع الصناعة التحويلية | AS5: قطاع التشييد والبناء | AT5: قطاع السياحة | AU5: قطاع النقل | AV5: قطاع الاتصالات | AW5: قطاع الخدمات المالية | AX5: قطاع الصناعة التحويلية | AY5: قطاع التشييد والبناء | AZ5: قطاع السياحة | BA5: قطاع النقل | BB5: قطاع الاتصالات | BC5: قطاع الخدمات المالية | BD5: قطاع الصناعة التحويلية | BE5: قطاع التشييد والبناء | BF5: قطاع السياحة | BG5: قطاع النقل | BH5: قطاع الاتصالات | BI5: قطاع الخدمات المالية | BJ5: قطاع الصناعة التحويلية | BK5: قطاع التشييد والبناء | BL5: قطاع السياحة | BM5: قطاع النقل | BN5: قطاع الاتصالات | BO5: قطاع الخدمات المالية | BP5: قطاع الصناعة التحويلية | BQ5: قطاع التشييد والبناء | BR5: قطاع السياحة | BS5: قطاع النقل | BT5: قطاع الاتصالات | BU5: قطاع الخدمات المالية | BV5: قطاع الصناعة التحويلية | BW5: قطاع التشييد والبناء | BX5: قطاع السياحة | BY5: قطاع النقل | BZ5: قطاع الاتصالات | CA5: قطاع الخدمات المالية | CB5: قطاع الصناعة التحويلية | CC5: قطاع التشييد والبناء | CD5: قطاع السياحة | CE5: قطاع النقل | CF5: قطاع الاتصالات | CG5: قطاع الخدمات المالية | CH5: قطاع الصناعة التحويلية | CI5: قطاع التشييد والبناء | CJ5: قطاع السياحة | CK5: قطاع النقل | CL5: قطاع الاتصالات | CM5: قطاع الخدمات المالية | CN5: قطاع الصناعة التحويلية | CO5: قطاع التشييد والبناء | CP5: قطاع السياحة | CQ5: قطاع النقل | CR5: قطاع الاتصالات | CS5: قطاع الخدمات المالية | CT5: قطاع الصناعة التحويلية | CU5: قطاع التشييد والبناء | CV5: قطاع السياحة | CW5: قطاع النقل | CX5: قطاع الاتصالات | CY5: قطاع الخدمات المالية | CZ5: قطاع الصناعة التحويلية | DA5: قطاع التشييد والبناء | DB5: قطاع السياحة | DC5: قطاع النقل | DD5: قطاع الاتصالات | DE5: قطاع الخدمات المالية | DF5: قطاع الصناعة التحويلية | DG5: قطاع التشييد والبناء | DH5: قطاع السياحة | DI5: قطاع النقل | DJ5: قطاع الاتصالات | DK5: قطاع الخدمات المالية | DL5: قطاع الصناعة التحويلية | DM5: قطاع التشييد والبناء | DN5: قطاع السياحة | DO5: قطاع النقل | DP5: قطاع الاتصالات | DQ5: قطاع الخدمات المالية | DR5: قطاع الصناعة التحويلية | DS5: قطاع التشييد والبناء | DT5: قطاع السياحة | DU5: قطاع النقل | DV5: قطاع الاتصالات | DW5: قطاع الخدمات المالية | DX5: قطاع الصناعة التحويلية | DY5: قطاع التشييد والبناء | DZ5: قطاع السياحة | EA5: قطاع النقل | EB5: قطاع الاتصالات | EC5: قطاع الخدمات المالية | ED5: قطاع الصناعة التحويلية | EE5: قطاع التشييد والبناء | EF5: قطاع السياحة | EG5: قطاع النقل | EH5: قطاع الاتصالات | EI5: قطاع الخدمات المالية | EJ5: قطاع الصناعة التحويلية | EK5: قطاع التشييد والبناء | EL5: قطاع السياحة | EM5: قطاع النقل | EN5: قطاع الاتصالات | EO5: قطاع الخدمات المالية | EP5: قطاع الصناعة التحويلية | EQ5: قطاع التشييد والبناء | ER5: قطاع السياحة | ES5: قطاع النقل | ET5: قطاع الاتصالات | EU5: قطاع الخدمات المالية | EV5: قطاع الصناعة التحويلية | EW5: قطاع التشييد والبناء | EX5: قطاع السياحة | EY5: قطاع النقل | EZ5: قطاع الاتصالات | FA5: قطاع الخدمات المالية | FB5: قطاع الصناعة التحويلية | FC5: قطاع التشييد والبناء | FD5: قطاع السياحة | FE5: قطاع النقل | FF5: قطاع الاتصالات | FG5: قطاع الخدمات المالية | FH5: قطاع الصناعة التحويلية | FI5: قطاع التشييد والبناء | FJ5: قطاع السياحة | FK5: قطاع النقل | FL5: قطاع الاتصالات | FM5: قطاع الخدمات المالية | FN5: قطاع الصناعة التحويلية | FO5: قطاع التشييد والبناء | FP5: قطاع السياحة | FQ5: قطاع النقل | FR5: قطاع الاتصالات | FS5: قطاع الخدمات المالية | FT5: قطاع الصناعة التحويلية | FU5: قطاع التشييد والبناء | FV5: قطاع السياحة | FW5: قطاع النقل | FX5: قطاع الاتصالات | FY5: قطاع الخدمات المالية | FZ5: قطاع الصناعة التحويلية | GA5: قطاع التشييد والبناء | GB5: قطاع السياحة | GC5: قطاع النقل | GD5: قطاع الاتصالات | GE5: قطاع الخدمات المالية | GF5: قطاع الصناعة التحويلية | GG5: قطاع التشييد والبناء | GH5: قطاع السياحة | GI5: قطاع النقل | GJ5: قطاع الاتصالات | GK5: قطاع الخدمات المالية | GL5: قطاع الصناعة التحويلية | GM5: قطاع التشييد والبناء | GN5: قطاع السياحة | GO5: قطاع النقل | GP5: قطاع الاتصالات | GQ5: قطاع الخدمات المالية | GR5: قطاع الصناعة التحويلية | GS5: قطاع التشييد والبناء | GT5: قطاع السياحة | GU5: قطاع النقل | GV5: قطاع الاتصالات | GW5: قطاع الخدمات المالية | GX5: قطاع الصناعة التحويلية | GY5: قطاع التشييد والبناء | GZ5: قطاع السياحة | HA5: قطاع النقل | HB5: قطاع الاتصالات | HC5: قطاع الخدمات المالية
A6: ارتفاع تكاليف الطاقة والمياة | DF6: 100 | DG6: 100 | DH6: 43 | DI6: 100 | DJ6: 55 | DK6: 40 | DL6: 100 | DM6: 100 | DN6: 100 | DO6: 100 | DP6: 72.727273 | DQ6: - | DR6: 100 | DS6: 100 | DT6: 100 | DU6: - | DV6: 100 | DW6: - | DX6: 90.625 | DY6: 100 | DZ6: 60 | EA6: _ | EB6: 46.428571 | EC6: _ | ED6: 98.689956 | EE6: 96.428571 | EF6: 75 | EG6: 0 | EH6: 81.25 | EI6: 0 | EJ6: 98.237885 | EK6: 88.888889 | EL6: 100 | EM6: 92.857143 | EN6: 81.25 | EO6: 1.7857143 | EP6: 99 | EQ6: 100 | ER6: 82 | ES6: 96 | ET6: 84 | EU6: 0 | EV6: 96.888889 | EW6: 96.296296 | EX6: 62.857143 | EY6: 89.130435 | EZ6: 60.714286 | FA6: 0 | FB6: 97.413793 | FC6: 92 | FD6: 87.5 | FE6: 20.454545 | FF6: 81.25 | FG6: 0 | FH6: 100 | FI6: 98.214286 | FJ6: 84.615385 | FK6: 0 | FL6: 100 | FM6: 16.981132 | FN6: 100 | FO6: 87.804878 | FP6: 90 | FQ6: 0 | FR6: 76.923077 | FS6: 23.214286 | FT6: 89.371981 | FU6: 95.833333 | FV6: 100 | FW6: 100 | FX6: 90.322581 | FY6: 40.740741 | FZ6: 99 | GA6: 98 | GB6: 92 | GC6: 87 | GD6: 72 | GE6: 53 | GF6: 87.5 | GG6: 61.538462 | GH6: 72.727273 | GI6: 100 | GJ6: 41.37931 | GK6: 33.333333 | GL6: 100 | GM6: 62.745098 | GN6: 100 | GO6: 100 | GP6: 96 | GQ6: 30.612245 | GR6: 100 | GS6: 76.923077 | GT6: 100 | GU6: 95.833333 | GV6: 68 | GW6: 25.806452 | GX6: 94.086022 | GY6: 76.190476 | GZ6: 100 | HA6: 0 | HB6: 93.333333
A7: زيادة الرسوم المفروضة على الخدمات الحكومية | DF7: 83 | DG7: 96 | DH7: 86 | DI7: 25 | DJ7: 91 | DK7: 10 | DL7: 81.447964 | DM7: 87.272727 | DN7: 86.666667 | DO7: 12.222222 | DP7: 100 | DQ7: 34.799802 | DR7: 83.204931 | DS7: 90.566038 | DT7: 63.888889 | DU7: 43.091168 | DV7: 60 | DW7: 43.103448 | DX7: 68.75 | DY7: 78.431373 | DZ7: 42.5 | EA7: 30.952381 | EB7: 39.285714 | EC7: 53.333333 | ED7: 74.235808 | EE7: 83.928571 | EF7: 45 | EG7: 6.25 | EH7: 50 | EI7: 28.846154 | EJ7: 54.185022 | EK7: 59.259259 | EL7: 79.411765 | EM7: 71.428571 | EN7: 56.25 | EO7: 0 | EP7: 63 | EQ7: 57 | ER7: 79 | ES7: 70 | ET7: 63 | EU7: 19 | EV7: 52 | EW7: 68.518519 | EX7: 37.142857 | EY7: 60.869565 | EZ7: 28.571429 | FA7: 0 | FB7: 51.293103 | FC7: 58 | FD7: 57.5 | FE7: 20.454545 | FF7: 87.5 | FG7: 0 | FH7: 67.826087 | FI7: 55.357143 | FJ7: 38.461538 | FK7: 12.5 | FL7: 62.068966 | FM7: 15.09434 | FN7: 67.368421 | FO7: 60.97561 | FP7: 43.333333 | FQ7: 50 | FR7: 80.769231 | FS7: 28.571429 | FT7: 63.768116 | FU7: 64.583333 | FV7: 46.153846 | FW7: 21.212121 | FX7: 45.16129 | FY7: 20.37037 | FZ7: 57 | GA7: 90 | GB7: 37 | GC7: 30 | GD7: 60 | GE7: 42 | GF7: 62.019231 | GG7: 53.846154 | GH7: 51.515152 | GI7: 88.235294 | GJ7: 48.275862 | GK7: 53.333333 | GL7: 57.653061 | GM7: 37.254902 | GN7: 68.75 | GO7: 75.757576 | GP7: 72 | GQ7: 20.408163 | GR7: 57.948718 | GS7: 71.794872 | GT7: 58.333333 | GU7: 70.833333 | GV7: 72 | GW7: 11.290323 | GX7: 51.075269 | GY7: 52.380952 | GZ7: 20 | HA7: 15 | HB7: 20
A8: إجراءات التعامل مع الجهات الحكومية | DF8: 80 | DG8: 73 | DH8: 100 | DI8: 25 | DJ8: 100 | DK8: 25 | DL8: 71.945701 | DM8: 67.272727 | DN8: 73.333333 | DO8: 11.111111 | DP8: 100 | DQ8: 9.4908552 | DR8: 70.454545 | DS8: 69.811321 | DT8: 50 | DU8: 15.081909 | DV8: 80 | DW8: 3.4482759 | DX8: 67.857143 | DY8: 58.823529 | DZ8: 30 | EA8: 26.190476 | EB8: 60.714286 | EC8: 10 | ED8: 69.432314 | EE8: 66.071429 | EF8: 30 | EG8: 14.583333 | EH8: 68.75 | EI8: 0 | EJ8: 66.960352 | EK8: 50 | EL8: 61.764706 | EM8: 52.380952 | EN8: 68.75 | EO8: 1.7857143 | EP8: 65 | EQ8: 60 | ER8: 54 | ES8: 62 | ET8: 75 | EU8: 0 | EV8: 68.444444 | EW8: 61.111111 | EX8: 31.428571 | EY8: 56.521739 | EZ8: 64.285714 | FA8: 0 | FB8: 65.948276 | FC8: 58 | FD8: 52.5 | FE8: 22.727273 | FF8: 87.5 | FG8: 76.595745 | FH8: 68.26087 | FI8: 57.142857 | FJ8: 30.769231 | FK8: 16.666667 | FL8: 75.862069 | FM8: 43.396226 | FN8: 78.947368 | FO8: 65.853659 | FP8: 40 | FQ8: 37.5 | FR8: 84.615385 | FS8: 37.5 | FT8: 68.115942 | FU8: 70.833333 | FV8: 84.615385 | FW8: 0 | FX8: 77.419355 | FY8: 16.666667 | FZ8: 69 | GA8: 77 | GB8: 76 | GC8: 13 | GD8: 84 | GE8: 63 | GF8: 68.269231 | GG8: 65.384615 | GH8: 78.787879 | GI8: 55.882353 | GJ8: 93.103448 | GK8: 48.888889 | GL8: 63.77551 | GM8: 58.823529 | GN8: 40.625 | GO8: 0 | GP8: 80 | GQ8: 16.326531 | GR8: 69.230769 | GS8: 69.230769 | GT8: 66.666667 | GU8: 54.166667 | GV8: 96 | GW8: 6.4516129 | GX8: 55.913978 | GY8: 61.904762 | GZ8: 25 | HA8: 0 | HB8: 46.666667
A9: مشاكل اجراء التصدير | DF9: 74 | DG9: 90 | DH9: 64 | DI9: 71 | DJ9: 9 | DK9: 27 | DL9: 93.665158 | DM9: 98.181818 | DN9: 56.666667 | DO9: 100 | DP9: 50 | DQ9: - | DR9: 100.12797 | DS9: 90.566038 | DT9: 91.666667 | DU9: - | DV9: 80 | DW9: - | DX9: 66.517857 | DY9: 88.235294 | DZ9: 47.5 | EA9: _ | EB9: 17.857143 | EC9: _ | ED9: 83.842795 | EE9: 100 | EF9: 55 | EG9: 0 | EH9: 34.375 | EI9: 0 | EJ9: 87.665198 | EK9: 96.296296 | EL9: 64.705882 | EM9: 100 | EN9: 34.375 | EO9: 0 | EP9: 90 | EQ9: 89 | ER9: 64 | ES9: 96 | ET9: 50 | EU9: 0 | EV9: 81.777778 | EW9: 94.444444 | EX9: 57.142857 | EY9: 89.130435 | EZ9: 50 | FA9: 0 | FB9: 87.068966 | FC9: 94 | FD9: 57.5 | FE9: 22.727273 | FF9: 56.25 | FG9: 0 | FH9: 76.956522 | FI9: 87.5 | FJ9: 74.358974 | FK9: 0 | FL9: 75.862069 | FM9: 11.320755 | FN9: 80.526316 | FO9: 80.487805 | FP9: 83.333333 | FQ9: 0 | FR9: 84.615385 | FS9: 35.714286 | FT9: 24.637681 | FU9: 0 | FV9: 0 | FW9: 12.121212 | FX9: 0 | FY9: 0 | FZ9: 26 | GA9: 0 | GB9: 11 | GC9: 0 | GD9: 0 | GE9: 0 | GF9: 26.923077 | GG9: 0 | GH9: 0 | GI9: 0 | GJ9: 13.793103 | GK9: 0 | GL9: 25 | GM9: 0 | GN9: 0 | GO9: 0 | GP9: 0 | GQ9: 0 | GR9: 31.282051 | GS9: 0 | GT9: 0 | GU9: 0 | GV9: 4 | GW9: 0 | GX9: 17.204301 | GY9: 0 | GZ9: 0 | HA9: 20 | HB9: 0
A10: المنظومة الضريبية | DF10: 71 | DG10: 69 | DH10: 14 | DI10: 6 | DJ10: 64 | DK10: 100 | DL10: 57.013575 | DM10: 49.090909 | DN10: 80 | DO10: 11.111111 | DP10: 72.727273 | DQ10: 80.672269 | DR10: 60.909091 | DS10: 47.169811 | DT10: 61.111111 | DU10: 28.009259 | DV10: 68 | DW10: 82.758621 | DX10: 40.625 | DY10: 41.176471 | DZ10: 62.5 | EA10: 0 | EB10: 53.571429 | EC10: 85 | ED10: 39.30131 | EE10: 62.5 | EF10: 42.5 | EG10: 20.833333 | EH10: 43.75 | EI10: 76.923077 | EJ10: 51.54185 | EK10: 46.296296 | EL10: 70.588235 | EM10: 47.619048 | EN10: 50 | EO10: 100 | EP10: 53 | EQ10: 40 | ER10: 92 | ES10: 66 | ET10: 63 | EU10: 81 | EV10: 51.111111 | EW10: 57.407407 | EX10: 65.714286 | EY10: 60.869565 | EZ10: 64.285714 | FA10: 100 | FB10: 56.034483 | FC10: 44 | FD10: 80 | FE10: 29.545455 | FF10: 87.5 | FG10: 53.191489 | FH10: 58.26087 | FI10: 57.142857 | FJ10: 33.333333 | FK10: 25 | FL10: 79.310345 | FM10: 90.566038 | FN10: 67.368421 | FO10: 51.219512 | FP10: 63.333333 | FQ10: 30 | FR10: 88.461538 | FS10: 92.857143 | FT10: 67.149758 | FU10: 79.166667 | FV10: 97.435897 | FW10: 36.363636 | FX10: 83.870968 | FY10: 100 | FZ10: 70 | GA10: 73 | GB10: 61 | GC10: 35 | GD10: 100 | GE10: 27 | GF10: 63.461538 | GG10: 44.230769 | GH10: 63.636364 | GI10: 23.529412 | GJ10: 86.206897 | GK10: 42.222222 | GL10: 66.326531 | GM10: 43.137255 | GN10: 75 | GO10: 9.0909091 | GP10: 100 | GQ10: 0 | GR10: 49.230769 | GS10: 53.846154 | GT10: 50 | GU10: 50 | GV10: 96 | GW10: 40.322581 | GX10: 61.827957 | GY10: 45.238095 | GZ10: 50 | HA10: 15 | HB10: 83.333333
A11: صعوبة الحصول علي العمالة المؤهلة | DF11: 61 | DG11: 33 | DH11: 29 | DI11: 6 | DJ11: 45 | DK11: 13 | DL11: 44.343891 | DM11: 36.363636 | DN11: 13.333333 | DO11: 2.2222222 | DP11: 36.363636 | DQ11: 0 | DR11: 43.636364 | DS11: 16.981132 | DT11: 5.5555556 | DU11: 0 | DV11: 52 | DW11: 0 | DX11: 28.125 | DY11: 27.45098 | DZ11: 20 | EA11: 0 | EB11: 39.285714 | EC11: 7.5851852 | ED11: 29.257642 | EE11: 8.9285714 | EF11: 15 | EG11: 0 | EH11: 43.75 | EI11: 3.8461538 | EJ11: 29.515419 | EK11: 14.814815 | EL11: 8.8235294 | EM11: 28.571429 | EN11: 6.25 | EO11: 3.5714286 | EP11: 38 | EQ11: 17 | ER11: 0 | ES11: 13 | ET11: 9 | EU11: 0 | EV11: 45.777778 | EW11: 12.962963 | EX11: 8.5714286 | EY11: 10.869565 | EZ11: 42.857143 | FA11: 0 | FB11: 40.517241 | FC11: 16 | FD11: 32.5 | FE11: 2.2727273 | FF11: 78.125 | FG11: 10.638298 | FH11: 56.086957 | FI11: 28.571429 | FJ11: 46.153846 | FK11: 0 | FL11: 79.310345 | FM11: 13.207547 | FN11: 45.263158 | FO11: 12.195122 | FP11: 46.666667 | FQ11: 0 | FR11: 76.923077 | FS11: 19.642857 | FT11: 49.275362 | FU11: 37.5 | FV11: 23.076923 | FW11: 0 | FX11: 74.193548 | FY11: 3.7037037 | FZ11: 48 | GA11: 10 | GB11: 32 | GC11: 4 | GD11: 68 | GE11: 38 | GF11: 41.346154 | GG11: 13.461538 | GH11: 27.272727 | GI11: 11.764706 | GJ11: 31.034483 | GK11: 26.666667 | GL11: 53.571429 | GM11: 17.647059 | GN11: 37.5 | GO11: 6.0606061 | GP11: 76 | GQ11: 8.1632653 | GR11: 52.307692 | GS11: 20.512821 | GT11: 36.111111 | GU11: 12.5 | GV11: 72 | GW11: 0 | GX11: 72.043011 | GY11: 26.190476 | GZ11: 42.5 | HA11: 0 | HB11: 93.333333
A12: ارتفاع التضخم | DF12: 53 | DG12: 83 | DH12: 57 | DI12: 35 | DJ12: 45 | DK12: 27 | DL12: 89.37984 | DM12: 92.727273 | DN12: 73.333333 | DO12: 12.777778 | DP12: 68.181818 | DQ12: 18.98171 | DR12: 95.454545 | DS12: 96.226415 | DT12: 83.333333 | DU12: 79.718661 | DV12: 84 | DW12: 79.310345 | DX12: 100 | DY12: 100 | DZ12: 100 | EA12: 97.619048 | EB12: 100 | EC12: 86.666667 | ED12: 100 | EE12: 98.214286 | EF12: 100 | EG12: 85.416667 | EH12: 100 | EI12: 100 | EJ12: 100 | EK12: 100 | EL12: 100 | EM12: 100 | EN12: 100 | EO12: 26.785714 | EP12: 100 | EQ12: 94 | ER12: 100 | ES12: 100 | ET12: 100 | EU12: 36 | EV12: 100 | EW12: 100 | EX12: 100 | EY12: 100 | EZ12: 100 | FA12: 26.984127 | FB12: 100 | FC12: 92 | FD12: 95 | FE12: 88.636364 | FF12: 100 | FG12: 0 | FH12: 100 | FI12: 96.428571 | FJ12: 100 | FK12: 95.833333 | FL12: 100 | FM12: 41.509434 | FN12: 98.421053 | FO12: 100 | FP12: 100 | FQ12: 30 | FR12: 100 | FS12: 33.928571 | FT12: 100 | FU12: 95.833333 | FV12: 100 | FW12: 93.939394 | FX12: 100 | FY12: 48.148148 | FZ12: 100 | GA12: 100 | GB12: 100 | GC12: 100 | GD12: 84 | GE12: 33 | GF12: 100 | GG12: 100 | GH12: 100 | GI12: 94.117647 | GJ12: 100 | GK12: 44.444444 | GL12: 97.959184 | GM12: 100 | GN12: 100 | GO12: 69.69697 | GP12: 96 | GQ12: 42.857143 | GR12: 93.333333 | GS12: 100 | GT12: 100 | GU12: 100 | GV12: 100 | GW12: 0 | GX12: 100 | GY12: 100 | GZ12: 97.5 | HA12: 80 | HB12: 100
A13: المنظومة الجمركية | DF13: 38 | DG13: 15 | DH13: 0 | DI13: 40 | DJ13: 36 | DK13: ــ | DL13: 67.836595 | DM13: 51.136364 | DN13: - | DO13: 21.728395 | DP13: 86.363636 | DQ13: - | DR13: 51.717172 | DS13: - | DT13: - | DU13: 14.543269 | DV13: 76 | DW13: - | DX13: 48.287172 | DY13: _ | DZ13: _ | EA13: 0 | EB13: 73.142857 | EC13: _ | ED13: 27.947598 | EE13: 5.3571429 | EF13: 0 | EG13: 8.3333333 | EH13: 53.125 | EI13: 0 | EJ13: 40.969163 | EK13: 25.925926 | EL13: 0 | EM13: 64.285714 | EN13: 25 | EO13: 0 | EP13: 40 | EQ13: 6 | ER13: 5 | ES13: 36 | ET13: 47 | EU13: 0 | EV13: 41.333333 | EW13: 7.4074074 | EX13: 5.7142857 | EY13: 36.956522 | EZ13: 21.428571 | FA13: 0 | FB13: 32.327586 | FC13: 6 | FD13: 30 | FE13: 13.636364 | FF13: 68.75 | FG13: 0 | FH13: 30.869565 | FI13: 7.1428571 | FJ13: 12.820513 | FK13: 8.3333333 | FL13: 31.034483 | FM13: 0 | FN13: 36.315789 | FO13: 0 | FP13: 3.3333333 | FQ13: 0 | FR13: 50 | FS13: 8.9285714 | FT13: 43.478261 | FU13: 4.1666667 | FV13: 0 | FW13: 0 | FX13: 48.387097 | FY13: 0 | FZ13: 43 | GA13: 0 | GB13: 11 | GC13: 9 | GD13: 48 | GE13: 0 | GF13: 38.461538 | GG13: 0 | GH13: 12.121212 | GI13: 44.117647 | GJ13: 20.689655 | GK13: 0 | GL13: 32.142857 | GM13: 3.9215686 | GN13: 9.375 | GO13: 48.484848 | GP13: 44 | GQ13: 0 | GR13: 37.435897 | GS13: 0 | GT13: 11.111111 | GU13: 12.5 | GV13: 32 | GW13: 0 | GX13: 28.494624 | GY13: 0 | GZ13: 0 | HA13: 100 | HB13: 36.666667
A14: تخبط السياسات الاقتصادية | DF14: 29 | DG14: 6 | DH14: 43 | DI14: 6 | DJ14: 45 | DK14: 98 | DL14: 24.434389 | DM14: 12.727273 | DN14: 13.333333 | DO14: 20.495868 | DP14: 0 | DQ14: 80.672269 | DR14: 37.272727 | DS14: 3.7735849 | DT14: 25 | DU14: 96.955128 | DV14: 16 | DW14: 100 | DX14: 32.589286 | DY14: 7.8431373 | DZ14: 15 | EA14: 95.238095 | EB14: 21.428571 | EC14: 100 | ED14: 29.694323 | EE14: 0 | EF14: 0 | EG14: 97.916667 | EH14: 28.125 | EI14: 90.384615 | EJ14: 44.493392 | EK14: 3.7037037 | EL14: 61.764706 | EM14: 0 | EN14: 50 | EO14: 100 | EP14: 50 | EQ14: 13 | ER14: 26 | ES14: 4 | ET14: 47 | EU14: 100 | EV14: 44 | EW14: 14.814815 | EX14: 11.428571 | EY14: 4.3478261 | EZ14: 25 | FA14: 100 | FB14: 51.293103 | FC14: 18 | FD14: 17.5 | FE14: 54.545455 | FF14: 56.25 | FG14: 100 | FH14: 67.826087 | FI14: 23.214286 | FJ14: 20.512821 | FK14: 100 | FL14: 62.068966 | FM14: 100 | FN14: 68.947368 | FO14: 17.073171 | FP14: 30 | FQ14: 100 | FR14: 80.769231 | FS14: 98.214286 | FT14: 56.521739 | FU14: 72.916667 | FV14: 41.025641 | FW14: 36.363636 | FX14: 64.516129 | FY14: 98.148148 | FZ14: 66 | GA14: 52 | GB14: 34 | GC14: 0 | GD14: 72 | GE14: 19 | GF14: 50.961538 | GG14: 50 | GH14: 24.242424 | GI14: 29.411765 | GJ14: 79.310345 | GK14: 31.111111 | GL14: 42.346939 | GM14: 43.137255 | GN14: 9.375 | GO14: 0 | GP14: 44 | GQ14: 16.326531 | GR14: 52.820513 | GS14: 58.974359 | GT14: 30.555556 | GU14: 0 | GV14: 64 | GW14: 0 | GX14: 37.096774 | GY14: 59.52381 | GZ14: 15 | HA14: 15 | HB14: 10
A15: انقطاع الكهرباء | DF15: 24 | DG15: 38 | DH15: 14 | DI15: 5 | DJ15: 0 | DK15: 0 | DL15: 18.552036 | DM15: 20 | DN15: 0 | DO15: 3.3333333 | DP15: 0 | DQ15: 0 | DR15: 9.0909091 | DS15: 1.8867925 | DT15: 13.888889 | DU15: 8.6182336 | DV15: 0 | DW15: 0 | DX15: 3.5714286 | DY15: 11.764706 | DZ15: 5 | EA15: 9.5238095 | EB15: 0 | EC15: 13.333333 | ED15: 6.1135371 | EE15: 1.7857143 | EF15: 0 | EG15: 8.3333333 | EH15: 0 | EI15: 0 | EJ15: 28.193833 | EK15: 18.518519 | EL15: 17.647059 | EM15: 23.809524 | EN15: 0 | EO15: 0 | EP15: 28 | EQ15: 11 | ER15: 0 | ES15: 21 | ET15: 6 | EU15: 0 | EV15: 20 | EW15: 16.666667 | EX15: 0 | EY15: 17.391304 | EZ15: 0 | FA15: 0 | FB15: 17.672414 | FC15: 12 | FD15: 0 | FE15: 2.2727273 | FF15: 50 | FG15: 6.3829787 | FH15: 13.043478 | FI15: 14.285714 | FJ15: 0 | FK15: 0 | FL15: 20.689655 | FM15: 30.188679 | FN15: 11.578947 | FO15: 26.829268 | FP15: 0 | FQ15: 10 | FR15: 42.307692 | FS15: 26.785714 | FT15: 48.792271 | FU15: 100 | FV15: 64.102564 | FW15: 66.666667 | FX15: 58.064516 | FY15: 70.37037 | FZ15: 6 | GA15: 8 | GB15: 11 | GC15: 0 | GD15: 16 | GE15: 3 | GF15: 15.384615 | GG15: 15.384615 | GH15: 6.0606061 | GI15: 0 | GJ15: 17.241379 | GK15: 8.8888889 | GL15: 11.22449 | GM15: 5.8823529 | GN15: 0 | GO15: 0 | GP15: 0 | GQ15: 0 | GR15: 13.846154 | GS15: 2.5641026 | GT15: 5.5555556 | GU15: 0 | GV15: 0 | GW15: 12.903226 | GX15: 13.978495 | GY15: 11.904762 | GZ15: 0 | HA15: 0 | HB15: 0
A16: غياب المعلومات عن السوق المحلي والخارجي | DF16: 19 | DG16: 25 | DH16: 0 | DI16: 31 | DJ16: 45 | DK16: 17 | DL16: 26.244344 | DM16: 36.363636 | DN16: 0 | DO16: 1.1111111 | DP16: 0 | DQ16: 0 | DR16: 18.636364 | DS16: 26.415094 | DT16: 0 | DU16: 5.1282051 | DV16: 16 | DW16: 3.4482759 | DX16: 8.9285714 | DY16: 7.8431373 | DZ16: 0 | EA16: 19.047619 | EB16: 17.857143 | EC16: 10 | ED16: 11.353712 | EE16: 12.5 | EF16: 0 | EG16: 0 | EH16: 18.75 | EI16: 0 | EJ16: 27.753304 | EK16: 24.074074 | EL16: 23.529412 | EM16: 26.190476 | EN16: 0 | EO16: 3.5714286 | EP16: 25 | EQ16: 13 | ER16: 0 | ES16: 28 | ET16: 0 | EU16: 0 | EV16: 11.555556 | EW16: 16.666667 | EX16: 0 | EY16: 23.913043 | EZ16: 0 | FA16: 0 | FB16: 18.103448 | FC16: 28 | FD16: 0 | FE16: 6.8181818 | FF16: 9.375 | FG16: 14.893617 | FH16: 16.956522 | FI16: 21.428571 | FJ16: 0 | FK16: 0 | FL16: 13.793103 | FM16: 20.754717 | FN16: 27.894737 | FO16: 26.829268 | FP16: 0 | FQ16: 0 | FR16: 26.923077 | FS16: 32.142857 | FT16: 50.724638 | FU16: 25 | FV16: 28.205128 | FW16: 33.333333 | FX16: 67.741935 | FY16: 11.111111 | FZ16: 48 | GA16: 10 | GB16: 16 | GC16: 0 | GD16: 32 | GE16: 3 | GF16: 42.307692 | GG16: 26.923077 | GH16: 6.0606061 | GI16: 8.8235294 | GJ16: 24.137931 | GK16: 6.6666667 | GL16: 24.489796 | GM16: 7.8431373 | GN16: 0 | GO16: 6.0606061 | GP16: 32 | GQ16: 0 | GR16: 37.948718 | GS16: 10.25641 | GT16: 16.666667 | GU16: 50 | GV16: 28 | GW16: 20.967742 | GX16: 30.645161 | GY16: 11.904762 | GZ16: 17.5 | HA16: 15 | HB16: 6.6666667
A17: أخرى | DF17: 13 | DG17: ــ | DH17: 50 | DI17: 20 | DJ17: 28 | DK17: 23 | DL17: 5.4298643 | DM17: 0 | DN17: 0 | DO17: 3.8888889 | DP17: 0 | DQ17: 94.908552 | DR17: 7.2727273 | DS17: 0 | DT17: 0 | DU17: 17.236467 | DV17: 0 | DW17: 41.37931 | DX17: 1.7857143 | DY17: 0 | DZ17: 0 | EA17: 0 | EB17: 0 | EC17: 40 | ED17: 0 | EE17: 0 | EF17: 0 | EG17: 8.3333333 | EH17: 0 | EI17: 46.153846 | EJ17: 1.7621145 | EK17: 0 | EL17: 0 | EM17: 0 | EN17: 0 | EO17: 35.714286 | EP17: 2 | EQ17: 0 | ER17: 0 | ES17: 0 | ET17: 0 | EU17: 56 | EV17: 3.1111111 | EW17: 0 | EX17: 8.5714286 | EY17: 0 | EZ17: 28.571429 | FA17: 25.396825 | FB17: 0 | FC17: 0 | FD17: 0 | FE17: 9.0909091 | FF17: 12.5 | FG17: 25.531915 | FH17: 13.913043 | FI17: 0 | FJ17: 10.25641 | FK17: 8.3333333 | FL17: 41.37931 | FM17: 15.09434 | FN17: 3.6842105 | FO17: 0 | FP17: 0 | FQ17: 20 | FR17: 0 | FS17: 44.642857 | FT17: 9.178744 | FU17: 8.3333333 | FV17: 33.333333 | FW17: 36.363636 | FX17: 38.709677 | FY17: 14.814815 | FZ17: 4 | GA17: 0 | GB17: 0 | GC17: 0 | GD17: 0 | GE17: 25 | GF17: 9.6153846 | GG17: 0 | GH17: 0 | GI17: 58.823529 | GJ17: 0 | GK17: 53.333333 | GL17: 4.0816327 | GM17: 0 | GN17: 0 | GO17: 36.363636 | GP17: 16 | GQ17: 65.306122 | GR17: 9.2307692 | GS17: 0 | GT17: 25 | GU17: 16.666667 | GV17: 0 | GW17: 77.419355 | GX17: 2.1505376 | GY17: 0 | GZ17: 0 | HA17: 40 | HB17: 0
A18: غموض توجهات السياسية الاقتصادية في المستقبل | DF18: 9 | DG18: 23 | DH18: 0 | DI18: 0 | DJ18: 0 | DK18: 0 | DL18: 4.0723982 | DM18: 20 | DN18: 0 | DO18: 1.1111111 | DP18: 0 | DQ18: 0 | DR18: 1.3636364 | DS18: 11.320755 | DT18: 0 | DU18: 0 | DV18: 0 | DW18: 0 | DX18: 1.7857143 | DY18: 7.8431373 | DZ18: 0 | EA18: 0 | EB18: 0 | EC18: 0 | ED18: 0.87336245 | EE18: 8.9285714 | EF18: 0 | EG18: 0 | EH18: 0 | EI18: 0 | EJ18: 14.096916 | EK18: 12.962963 | EL18: 11.764706 | EM18: 19.047619 | EN18: 0 | EO18: 0 | EP18: 16 | EQ18: 11 | ER18: 0 | ES18: 17 | ET18: 0 | EU18: 0 | EV18: 8 | EW18: 3.7037037 | EX18: 0 | EY18: 15.217391 | EZ18: 0 | FA18: 0 | FB18: 7.3275862 | FC18: 12 | FD18: 0 | FE18: 0 | FF18: 0 | FG18: 0 | FH18: 1.7391304 | FI18: 10.714286 | FJ18: 0 | FK18: 0 | FL18: 6.8965517 | FM18: 11.320755 | FN18: 6.3157895 | FO18: 7.3170732 | FP18: 0 | FQ18: 0 | FR18: 19.230769 | FS18: 7.1428571 | FT18: 72.463768 | FU18: 87.5 | FV18: 25.641026 | FW18: 60.606061 | FX18: 58.064516 | FY18: 100 | FZ18: 71 | GA18: 67 | GB18: 24 | GC18: 70 | GD18: 64 | GE18: 100 | GF18: 67.788462 | GG18: 42.307692 | GH18: 15.151515 | GI18: 70.588235 | GJ18: 34.482759 | GK18: 100 | GL18: 48.979592 | GM18: 31.372549 | GN18: 6.25 | GO18: 63.636364 | GP18: 60 | GQ18: 100 | GR18: 53.333333 | GS18: 56.410256 | GT18: 25 | GU18: 79.166667 | GV18: 36 | GW18: 100 | GX18: 39.784946 | GY18: 45.238095 | GZ18: 7.5 | HA18: 95 | HB18: 6.6666667
A19: الحصول على الخدمات التمويل | DF19: 7 | DG19: 8 | DH19: 0 | DI19: 40 | DJ19: 27 | DK19: ــ | DL19: 6.0242577 | DM19: 9.0909091 | DN19: 0 | DO19: 0 | DP19: 40.909091 | DQ19: - | DR19: 4.4893378 | DS19: 0 | DT19: 0 | DU19: 4.3091168 | DV19: 16 | DW19: - | DX19: 0 | DY19: 7.8431373 | DZ19: 2.5 | EA19: 76.190476 | EB19: 10.714286 | EC19: _ | ED19: 2.6200873 | EE19: 0 | EF19: 0 | EG19: 0 | EH19: 18.75 | EI19: 0 | EJ19: 10.572687 | EK19: 3.7037037 | EL19: 8.8235294 | EM19: 0 | EN19: 12.5 | EO19: 0 | EP19: 12 | EQ19: 6 | ER19: 0 | ES19: 0 | ET19: 28 | EU19: 0 | EV19: 8.8888889 | EW19: 0 | EX19: 0 | EY19: 0 | EZ19: 25 | FA19: 0 | FB19: 9.0517241 | FC19: 0 | FD19: 0 | FE19: 6.8181818 | FF19: 46.875 | FG19: 0 | FH19: 10.434783 | FI19: 3.5714286 | FJ19: 28.205128 | FK19: 6.25 | FL19: 58.62069 | FM19: 15.09434 | FN19: 19.473684 | FO19: 2.4390244 | FP19: 30 | FQ19: 10 | FR19: 53.846154 | FS19: 19.642857 | FT19: 19.806763 | FU19: 29.166667 | FV19: 30.769231 | FW19: 24.242424 | FX19: 58.064516 | FY19: 0 | FZ19: 19 | GA19: 31 | GB19: 42 | GC19: 0 | GD19: 40 | GE19: 0 | GF19: 32.211538 | GG19: 11.538462 | GH19: 18.181818 | GI19: 11.764706 | GJ19: 65.517241 | GK19: 0 | GL19: 32.142857 | GM19: 21.568627 | GN19: 6.25 | GO19: 12.121212 | GP19: 32 | GQ19: 0 | GR19: 25.641026 | GS19: 23.076923 | GT19: 11.111111 | GU19: 25 | GV19: 64 | GW19: 0 | GX19: 22.043011 | GY19: 26.190476 | GZ19: 20 | HA19: 0 | HB19: 66.666667
A20: النقل واللوجستيات | DF20: 7 | DG20: 6 | DH20: 0 | DI20: 40 | DJ20: 9 | DK20: ــ | DL20: 6.0242577 | DM20: 9.0909091 | DN20: 0 | DO20: 0 | DP20: 40.909091 | DQ20: - | DR20: 4.4893378 | DS20: 0 | DT20: 0 | DU20: 8.6182336 | DV20: 16 | DW20: - | DX20: 0 | DY20: 9.8039216 | DZ20: 0 | EA20: 76.190476 | EB20: 10.714286 | EC20: _ | ED20: 1.7467249 | EE20: 0 | EF20: 0 | EG20: 0 | EH20: 12.5 | EI20: 0 | EJ20: 8.8105727 | EK20: 3.7037037 | EL20: 8.8235294 | EM20: 0 | EN20: 15.625 | EO20: 0 | EP20: 10 | EQ20: 4 | ER20: 0 | ES20: 0 | ET20: 22 | EU20: 0 | EV20: 8 | EW20: 0 | EX20: 0 | EY20: 0 | EZ20: 28.571429 | FA20: 0 | FB20: 6.4655172 | FC20: 0 | FD20: 2.5 | FE20: 0 | FF20: 50 | FG20: 0 | FH20: 9.1304348 | FI20: 0 | FJ20: 23.076923 | FK20: 0 | FL20: 48.275862 | FM20: 9.4339623 | FN20: 18.421053 | FO20: 0 | FP20: 26.666667 | FQ20: 0 | FR20: 73.076923 | FS20: 19.642857 | FT20: 31.884058 | FU20: 37.5 | FV20: 46.153846 | FW20: 12.121212 | FX20: 38.709677 | FY20: 0 | FZ20: 40 | GA20: 8 | GB20: 37 | GC20: 7 | GD20: 28 | GE20: 0 | GF20: 30.769231 | GG20: 9.6153846 | GH20: 27.272727 | GI20: 11.764706 | GJ20: 34.482759 | GK20: 4.4444444 | GL20: 48.979592 | GM20: 7.8431373 | GN20: 59.375 | GO20: 6.0606061 | GP20: 64 | GQ20: 0 | GR20: 47.179487 | GS20: 20.512821 | GT20: 41.666667 | GU20: 16.666667 | GV20: 36 | GW20: 0 | GX20: 54.83871 | GY20: 45.238095 | GZ20: 32.5 | HA20: 0 | HB20: 43.333333
A21: سعر الصرف | DF21: 7 | DG21: 10 | DH21: 0 | DI21: 0 | DJ21: 9 | DK21: 0 | DL21: 2.2624434 | DM21: 0 | DN21: 0 | DO21: 0 | DP21: 0 | DQ21: 0 | DR21: 86.363636 | DS21: 83.018868 | DT21: 66.666667 | DU21: 100 | DV21: 72 | DW21: 0 | DX21: 86.797718 | DY21: 94.117647 | DZ21: 65 | EA21: 100 | EB21: 71 | EC21: 55 | ED21: 86.026201 | EE21: 94.642857 | EF21: 100 | EG21: 100 | EH21: 100 | EI21: 15.384615 | EJ21: 91.629956 | EK21: 100 | EL21: 91.176471 | EM21: 97.619048 | EN21: 90.625 | EO21: 0 | EP21: 96 | EQ21: 98 | ER21: 87 | ES21: 100 | ET21: 100 | EU21: 6 | EV21: 90.666667 | EW21: 100 | EX21: 65.714286 | EY21: 91.304348 | EZ21: 53.571429 | FA21: 80.952381 | FB21: 92.672414 | FC21: 100 | FD21: 92.5 | FE21: 100 | FF21: 78.125 | FG21: 40.425532 | FH21: 96.086957 | FI21: 100 | FJ21: 87.179487 | FK21: 100 | FL21: 100 | FM21: 39.622642 | FN21: 91.052632 | FO21: 82.926829 | FP21: 96.666667 | FQ21: 100 | FR21: 96.153846 | FS21: 100 | FT21: 76.328502 | FU21: 93.75 | FV21: 15.384615 | FW21: 84.848485 | FX21: 25.806452 | FY21: 27.777778 | FZ21: 59 | GA21: 83 | GB21: 26 | GC21: 4 | GD21: 52 | GE21: 6 | GF21: 68.75 | GG21: 96.153846 | GH21: 60.606061 | GI21: 32.352941 | GJ21: 93.103448 | GK21: 20 | GL21: 46.428571 | GM21: 82.352941 | GN21: 37.5 | GO21: 0 | GP21: 48 | GQ21: 0 | GR21: 38.461538 | GS21: 92.307692 | GT21: 30.555556 | GU21: 0 | GV21: 40 | GW21: 0 | GX21: 37.634409 | GY21: 78.571429 | GZ21: 2.5 | HA21: 0 | HB21: 13.333333
A22: عدم تفضيل المنتج المحلي في التعاقدات الحكومية | DF22: 1 | DG22: 4 | DH22: 7 | DI22: 0 | DJ22: 0 | DK22: ــ | DL22: 1.8072773 | DM22: 3.6363636 | DN22: 0 | DO22: 0 | DP22: 0 | DQ22: - | DR22: 10.662177 | DS22: 0 | DT22: 11.111111 | DU22: 0 | DV22: 16 | DW22: - | DX22: 0 | DY22: 13.72549 | DZ22: 0 | EA22: 76.190476 | EB22: 4 | EC22: _ | ED22: 2.1834061 | EE22: 0 | EF22: 0 | EG22: 0 | EH22: 12.5 | EI22: 0 | EJ22: 21.145374 | EK22: 5.5555556 | EL22: 55.882353 | EM22: 0 | EN22: 53.125 | EO22: 1.7857143 | EP22: 23 | EQ22: 8 | ER22: 79 | ES22: 0 | ET22: 50 | EU22: 0 | EV22: 20.444444 | EW22: 7.4074074 | EX22: 71.428571 | EY22: 0 | EZ22: 57.142857 | FA22: 0 | FB22: 25 | FC22: 0 | FD22: 100 | FE22: 6.8181818 | FF22: 90.625 | FG22: 0 | FH22: 33.478261 | FI22: 8.9285714 | FJ22: 87.179487 | FK22: 6.25 | FL22: 82.758621 | FM22: 16.981132 | FN22: 44.210526 | FO22: 4.8780488 | FP22: 83.333333 | FQ22: 10 | FR22: 92.307692 | FS22: 33.928571 | FT22: 36.231884 | FU22: 29.166667 | FV22: 5.1282051 | FW22: 0 | FX22: 35.483871 | FY22: 9.2592593 | FZ22: 22 | GA22: 8 | GB22: 0 | GC22: 0 | GD22: 32 | GE22: 3 | GF22: 15.384615 | GG22: 17.307692 | GH22: 6.0606061 | GI22: 0 | GJ22: 20.689655 | GK22: 0 | GL22: 12.244898 | GM22: 3.9215686 | GN22: 0 | GO22: 0 | GP22: 16 | GQ22: 0 | GR22: 12.820513 | GS22: 2.5641026 | GT22: 0 | GU22: 0 | GV22: 8 | GW22: 0 | GX22: 10.752688 | GY22: 7.1428571 | GZ22: 0 | HA22: 0 | HB22: 3.3333333
A23: المنافسة غير العادلة من الدولة | DF23: 0 | DG23: 0 | DH23: 0 | DI23: 0 | DJ23: 0 | DK23: 71 | DL23: 7.1674208 | DM23: 8.3487941 | DN23: 0 | DO23: - | DP23: 0 | DQ23: 100 | DR23: 0 | DS23: 0 | DT23: 0 | DU23: - | DV23: 0 | DW23: 68.965517 | DX23: 0 | DY23: 4.5480914 | DZ23: 0 | EA23: _ | EB23: 0 | EC23: 80 | ED23: 0 | EE23: 0 | EF23: 0 | EG23: 0 | EH23: 0 | EI23: 0 | EJ23: 0.88105727 | EK23: 1.8518519 | EL23: 2.9411765 | EM23: 7.1428571 | EN23: 0 | EO23: 7.1428571 | EP23: 3 | EQ23: 2 | ER23: 0 | ES23: 0 | ET23: 0 | EU23: 0 | EV23: 0 | EW23: 0 | EX23: 0 | EY23: 0 | EZ23: 0 | FA23: 9.5238095 | FB23: 0 | FC23: 0 | FD23: 0 | FE23: 0 | FF23: 0 | FG23: 17.021277 | FH23: 1.3043478 | FI23: 0 | FJ23: 0 | FK23: 0 | FL23: 6.8965517 | FM23: 30.188679 | FN23: 5.7894737 | FO23: 0 | FP23: 3.3333333 | FQ23: 0 | FR23: 15.384615 | FS23: 39.285714 | FT23: 28.985507 | FU23: 97.916667 | FV23: 28.205128 | FW23: 0 | FX23: 70.967742 | FY23: 11.111111 | FZ23: 28 | GA23: 94 | GB23: 13 | GC23: 0 | GD23: 56 | GE23: 6 | GF23: 21.153846 | GG23: 80.769231 | GH23: 0 | GI23: 5.8823529 | GJ23: 37.931034 | GK23: 8.8888889 | GL23: 18.367347 | GM23: 47.058824 | GN23: 9.375 | GO23: 0 | GP23: 56 | GQ23: 0 | GR23: 13.333333 | GS23: 58.974359 | GT23: 11.111111 | GU23: 0 | GV23: 60 | GW23: 0 | GX23: 6.4516129 | GY23: 40.47619 | GZ23: 5 | HA23: 0 | HB23: 6.6666667

Sheet Sectoral Constraints Fig 2-3 EN
B1: Jan - Mar 2017 | H1: Apr - Jun 2017 | N1: Jul - Sep 2017 | T1: Oct - Dec 2017 | Z1: Jan - Mar 2018 | AF1: Apr - Jun 2018 | AL1: Jul - Sep 2018 | AR1: Oct - Dec 2018 | AX1: Jan - Mar 2019 | BD1: Apr - Jun 2019 | BJ1: Jul - Sep 2019 | BP1: Oct - Dec 2019 | BV1: Jan - Mar 2020 | CB1: Apr - Jun 2020 | CH1: Jul - Sep 2020 | CN1: Oct - Dec 2020 | CT1: Jan - Mar 2021 | CZ1: Apr - Jun 2021 | DF1: Jul - Sep 2021 | DL1: Oct - Dec 2021 | DR1: Jan - Mar 2022 | DX1: Apr - June 2022 | ED1: Jul - Sep 2022 | EJ1: Oct - Dec 2022 | EP1: Jan - Mar 2023 | EV1: Apr - June 2023
B5: Manufacturing | C5: Construction | D5: Tourism | E5: Transport | F5: Communications | G5: Financial Services | H5: Manufacturing | I5: Construction | J5: Tourism | K5: Transport | L5: Communications | M5: Financial Services | N5: Manufacturing | O5: Construction | P5: Tourism | Q5: Transport | R5: Communications | S5: Financial Services | T5: Manufacturing | U5: Construction | V5: Tourism | W5: Transport | X5: Communications | Y5: Financial Services | Z5: Manufacturing | AA5: Construction | AB5: Tourism | AC5: Transport | AD5: Communications | AE5: Financial Services | AF5: Manufacturing | AG5: Construction | AH5: Tourism | AI5: Transport | AJ5: Communications | AK5: Financial Services | AL5: Manufacturing | AM5: Construction | AN5: Tourism | AO5: Transport | AP5: Communications | AQ5: Financial Services | AR5: Manufacturing | AS5: Construction | AT5: Tourism | AU5: Transport | AV5: Communications | AW5: Financial Services | AX5: Manufacturing | AY5: Construction | AZ5: Tourism | BA5: Transport | BB5: Communications | BC5: Financial Services | BD5: Manufacturing | BE5: Construction | BF5: Tourism | BG5: Transport | BH5: Communications | BI5: Financial Services | BJ5: Manufacturing | BK5: Construction | BL5: Tourism | BM5: Transport | BN5: Communications | BO5: Financial Services | BP5: Manufacturing | BQ5: Construction | BR5: Tourism | BS5: Transport | BT5: Communications | BU5: Financial Services | BV5: Manufacturing | BW5: Construction | BX5: Tourism | BY5: Transport | BZ5: Communications | CA5: Financial Services | CB5: Manufacturing | CC5: Construction | CD5: Tourism | CE5: Transport | CF5: Communications | CG5: Financial Services | CH5: Manufacturing | CI5: Construction | CJ5: Tourism | CK5: Transport | CL5: Communications | CM5: Financial Services | CN5: Manufacturing | CO5: Construction | CP5: Tourism | CQ5: Transport | CR5: Communications | CS5: Financial Services | CT5: Manufacturing | CU5: Construction | CV5: Tourism | CW5: Transport | CX5: Communications | CY5: Financial Services | CZ5: Manufacturing | DA5: Construction | DB5: Tourism | DC5: Transport | DD5: Communications | DE5: Financial Services | DF5: Manufacturing | DG5: Construction | DH5: Tourism | DI5: Transport | DJ5: Communications | DK5: Financial Services | DL5: Manufacturing | DM5: Construction | DN5: Tourism | DO5: Transport | DP5: Communications | DQ5: Financial Services | DR5: Manufacturing | DS5: Construction | DT5: Tourism | DU5: Transport | DV5: Communications | DW5: Financial Services | DX5: Manufacturing | DY5: Construction | DZ5: Tourism | EA5: Transport | EB5: Communications | EC5: Financial Services | ED5: Manufacturing | EE5: Construction | EF5: Tourism | EG5: Transport | EH5: Communications | EI5: Financial Services | EJ5: Manufacturing | EK5: Construction | EL5: Tourism | EM5: Transport | EN5: Communications | EO5: Financial Services | EP5: Manufacturing | EQ5: Construction | ER5: Tourism | ES5: Transport | ET5: Communications | EU5: Financial Services | EV5: Manufacturing | EW5: Construction | EX5: Tourism | EY5: Transport | EZ5: Communications | FA5: Financial Services
A6: High production costs | B6: ='Sectoral Constraints Fig 2-3 AR'!B6 -> 0 | C6: ='Sectoral Constraints Fig 2-3 AR'!C6 -> 0 | D6: ='Sectoral Constraints Fig 2-3 AR'!D6 -> 0 | E6: ='Sectoral Constraints Fig 2-3 AR'!E6 -> 0 | F6: ='Sectoral Constraints Fig 2-3 AR'!F6 -> 0 | G6: ='Sectoral Constraints Fig 2-3 AR'!G6 -> 0 | H6: ='Sectoral Constraints Fig 2-3 AR'!H6 -> 0 | I6: ='Sectoral Constraints Fig 2-3 AR'!I6 -> 0 | ... DW6: ='Sectoral Constraints Fig 2-3 AR'!DW6 -> - | DX6: 90.625 | DY6: 100 | DZ6: 60 | EA6: _ | EB6: 46.428571 | EC6: _ | ED6: 98.689956 | EE6: 96.428571 | EF6: 75 | EG6: 0 | EH6: 81.25 | EI6: 0 | EJ6: 98.237885 | EK6: 88.888889 | EL6: 100 | EM6: 92.857143 | EN6: 81.25 | EO6: 1.7857143 | EP6: 99 | EQ6: 100 | ER6: 82 | ES6: 96 | ET6: 84 | EU6: 0 | EV6: 96.888889 | EW6: 96.296296 | EX6: 62.857143 | EY6: 89.130435 | EZ6: 60.714286 | FA6: 0
A7: Increased government services fees | B7: ='Sectoral Constraints Fig 2-3 AR'!B7 -> 0 | C7: ='Sectoral Constraints Fig 2-3 AR'!C7 -> 0 | D7: ='Sectoral Constraints Fig 2-3 AR'!D7 -> 0 | E7: ='Sectoral Constraints Fig 2-3 AR'!E7 -> 0 | F7: ='Sectoral Constraints Fig 2-3 AR'!F7 -> 0 | G7: ='Sectoral Constraints Fig 2-3 AR'!G7 -> 0 | H7: ='Sectoral Constraints Fig 2-3 AR'!H7 -> 0 | I7: ='Sectoral Constraints Fig 2-3 AR'!I7 -> 0 | ... DW7: ='Sectoral Constraints Fig 2-3 AR'!DW7 -> 43.103448 | DX7: 68.75 | DY7: 78.431373 | DZ7: 42.5 | EA7: 30.952381 | EB7: 39.285714 | EC7: 53.333333 | ED7: 74.235808 | EE7: 83.928571 | EF7: 45 | EG7: 6.25 | EH7: 50 | EI7: 28.846154 | EJ7: 54.185022 | EK7: 59.259259 | EL7: 79.411765 | EM7: 71.428571 | EN7: 56.25 | EO7: 0 | EP7: 63 | EQ7: 57 | ER7: 79 | ES7: 70 | ET7: 63 | EU7: 19 | EV7: 52 | EW7: 68.518519 | EX7: 37.142857 | EY7: 60.869565 | EZ7: 28.571429 | FA7: 0
